Workbook

Sheet Project Details
B2: NIU KQi 100P Scooter | E2: Assumption
B3: Cost | C3: 300 | E3: Mass Order Discount | F3: 0.1
B4: Units | C4: 150 | E4: Project Life (Years) | F4: 5
E5: Universal Inflation Rate | F5: 0.035
B6: Specs | E6: University MARR | F6: 0.08
B7: Battery (Wh) | C7: 243 | E7: Hourly Retrofitting Labor Rate | F7: 100
B8: Battery (kWh) | C8: =C7/1000 -> 0.243
B9: Range (mi) | C9: 18 | E9: Spare Parts Stock
B10: Charge Time (hr) | C10: 5.5 | E10: Part | F10: 2 Month Need | G10: + Safety Factor | H10: Cost Per Part | I10: Total
E11: Tires | F11: =ROUNDUP(Maintenance!G4/6,0) -> 4 | G11: =ROUNDUP(1.5*F11,0) -> 6 | H11: 39.8 | I11: =H11*G11 -> 238.8
E12: Brakes | F12: =ROUNDUP(Maintenance!G5/6,0) -> 6 | G12: =ROUNDUP(1.5*F12,0) -> 9 | H12: 25 | I12: =H12*G12 -> 225
B13: Joyride Neon IoT (GeoFencing) | E13: Batteries | F13: =ROUNDUP(Maintenance!G6/6,0) -> 4 | G13: =ROUNDUP(1.5*F13,0) -> 6 | H13: 105 | I13: =H13*G13 -> 630
B14: Joyride Scale Monthly Fee | C14: 2500 | E14: Frame | F14: =ROUNDUP(Maintenance!G7/6,0) -> 1 | G14: =ROUNDUP(1.5*F14,0) -> 2 | H14: 240 | I14: =H14*G14 -> 480
B15: Monthly Fee/Unit (After 150) | C15: 8 | E15: Electric | F15: =ROUNDUP(Maintenance!G8/6,0) -> 3 | G15: =ROUNDUP(1.5*F15,0) -> 5 | H15: 40 | I15: =H15*G15 -> 200
B16: IoT Modules | C16: 100 | E16: Lights | F16: =ROUNDUP(Maintenance!G9/6,0) -> 6 | G16: =ROUNDUP(1.5*F16,0) -> 9 | H16: 25 | I16: =H16*G16 -> 225
B17: Software Setup | C17: 1000 | E17: Total | I17: =SUM(I11:I16) -> 1998.8
B19: Kuhmute Smart Hub Station
B20: Ports/Station | C20: 20
B21: Stations | C21: 6
B22: MLCS Unit Adapter | C22: 70
B23: 10-Port Station | C23: 15000
B24: Soft-Ware Setup | C24: 1000
B26: Site Development (5 Stations)
B27: Eletrical Trenching | C27: 45000
B28: Concrete Pads | C28: 18000
B29: Eletrical Hookup | C29: 12000
B30: Campus Sight Markers/Barriors | C30: 6000
B31: On-Site Storage Allocation | C31: 3000
B32: Contingency | C32: 0.1
B34: Single Unit Retrofitting Labor Hours
B35: IoT Modules | C35: 0.5
B36: MLCS Unit Adapter | C36: 1
B38: Permits
B39: CSU Building | C39: 1500
B40: ADA Title 24 Review | C40: 2500
B41: Eletetrical Plan Review | C41: 1000
B42: Fire Marshal Review | C42: 2000
B43: EHS | C43: 1500
B44: SMOP (Annual) | C44: 2500
B46: Revenue
...

Sheet Maintenance
M1: Example Reliability Data Log
B2: Outsource $/Year | E2: Annual Corrective Maintenance | M2: scooter_id | N2: in_service_date | O2: odometer_miles | P2: failure_datetime | Q2: failure_mode | R2: severity | S2: repair_start | T2: repair_end | U2: repair_action | V2: parts_cost | W2: labor_hours | X2: return_to_service
B3: Hourly | C3: 100 | E3: Type | F3: Reliability | G3: # Repairs | H3: Cost | M3: 2432 | N3: 46379 | O3: 142 | P3: 46378 | Q3: Tires | R3: 1 | S3: 46379.524 | T3: 46380.541 | U3: Replace Tires | V3: 39.8 | W3: =T3-S3 -> 1.0173611 | X3: 46385.542
B4: MTTR Corrective(hr) | C4: 1 | E4: Tires | F4: 0.85 | G4: =(1-F4)*'Project Details'!$C$4 -> 22.5 | H4: =C14*G4 -> 895.5 | M4: 2433 | N4: 46380 | O4: 143 | P4: 46379 | Q4: Brakes | R4: 2 | S4: 46379.524 | T4: 46380.541 | U4: Replace Brake | V4: =C15 -> 25 | W4: =T4-S4 -> 1.0173611 | X4: 46386.542
B5: MTTR Preventative(hr) | C5: 0.5 | E5: Brakes | F5: 0.79 | G5: =(1-F5)*'Project Details'!$C$4 -> 31.5 | H5: =C15*G5 -> 787.5 | M5: 2434 | N5: 46381 | O5: 144 | P5: 46380 | Q5: Batteries | R5: 3 | S5: 46379.524 | T5: 46380.541 | U5: Replace Battery | V5: =C16 -> 105 | W5: =T5-S5 -> 1.0173611 | X5: 46387.542
B6: MTBF Corrective (hr) | C6: =8760/C8 -> 69.52381 | E6: Batteries | F6: 0.85 | G6: =(1-F6)*'Project Details'!$C$4 -> 22.5 | H6: =C16*G6 -> 2362.5
B7: MTBR Preventative (hr) | C7: =8760/C9 -> 14.025026 | E7: Frame | F7: 0.99 | G7: =(1-F7)*'Project Details'!$C$4 -> 1.5 | H7: =C17*G7 -> 360
B8: JOBS Corrective | C8: =G10 -> 126 | E8: Controller | F8: 0.89 | G8: =(1-F8)*'Project Details'!$C$4 -> 16.5 | H8: =C18*G8 -> 660
B9: JOBS Prevantative | C9: =G21 -> 624.59776 | E9: Lights | F9: 0.79 | G9: =(1-F9)*'Project Details'!$C$4 -> 31.5 | H9: =C19*G9 -> 787.5
B10: Total Time (hr) | C10: =C4*C8+C9*C5 -> 438.29888 | E10: Overall | F10: =AVERAGE(F4:F9) -> 0.86 | G10: =SUM(G4:G9) -> 126 | H10: =SUM(H4:H9) -> 5853
B11: Total Cost | C11: =C10*C3 -> 43829.888
B13: Parts Costs | E13: Annual Preventative Maintenance
B14: Tires | C14: 39.8 | E14: Annual Fleet Miles | G14: =Usability!I4*12 -> 124629.04
B15: Brakes | C15: 25 | E15: Type | F15: MMBF | G15: ∑ Replacements | H15: Cost
B16: Batteries | C16: 105 | E16: Tires | F16: 450 | G16: =$G$14/F16 -> 276.95342 | H16: =C14*G16 -> 11022.746
B17: Frame | C17: 240 | E17: Brakes | F17: 900 | G17: =$G$14/F17 -> 138.47671 | H17: =C15*G17 -> 3461.9178
B18: Electric | C18: 40 | E18: Batteries | F18: 1300 | G18: =$G$14/F18 -> 95.868493 | H18: =C16*G18 -> 10066.192
B19: Lights | C19: 25 | E19: Controller | F19: 2200 | G19: =$G$14/F19 -> 56.649564 | H19: =C18*G19 -> 2265.9826
E20: Lights | F20: 2200 | G20: =$G$14/F20 -> 56.649564 | H20: =C19*G20 -> 1416.2391
B21: Inhouse Labor Option | E21: Overall | F21: =AVERAGE(F16:F20) -> 1410 | G21: =SUM(G16:G20) -> 624.59776 | H21: =SUM(H16:H20) -> 28233.078
B22: Employees | C22: 2 | E22: MMBF = Mean miles before failure
B23: Salary/Each | C23: 40000 | F23: Monthy Cost
B24: Benefits/Each | C24: 10000 | F24: Parts | G24: =(H10+H21)/12 -> 2840.5065
B25: Total | C25: =SUM(C23:C24)*C22 -> 100000 | F25: Labor | G25: =C11/12 -> 3652.4907
F26: Total | G26: =SUM(G24:G25) -> 6492.9971

Sheet Usability
B2: Parameter | C2: Estimate | D2: Notes | E2: Estimate Classification | H2: Montly Averages
B3: Active Hours Per Day | C3: 12 | D3: 9am-9PM | E3: Aggressive | H3: Trips | I3: =($C$6/365)*30*C15 -> 13847.671
B4: Active Months Per year | C4: 9 | D4: Fall/Spring Semesters | E4: Moderate | H4: Fleet Miles | I4: =($C$6/365)*30*C16 -> 10385.753
B5: Active Days Per Week | C5: 5 | D5: Monday-Friday | E5: Moderate | H5: Unit Miles | I5: =I4/C18 -> 86.547945
B6: Active Days/Year | C6: =ROUND(C4*4.33*C5,0) -> 195 | D6: -
B7: Peak Hours | C7: 5 | D7: 10am-3pm | E7: Conservative
B8: Enrolled Students | C8: 12000 | D8: Based on 2025 Year Enrollment | E8: Moderate
B9: On-Campus Population % | C9: 0.6 | D9: Consistent Campus Students | E9: Moderate
B10: Adoption % | C10: ='PROJECT ANALYSIS'!B3 -> 0.12 | D10: Younger Population Interest | E10: Moderate
B11: Average Trip | C11: 0.75 | D11: Campus size | E11: Moderate
B12: Avg Daily Rides Per User | C12: 1 | D12: Campus Enthusasim | E12: Moderate
B14: Opt-in Users | C14: =C8*C9*C10 -> 864
B15: Daily Trips | C15: =C14*C12 -> 864
B16: Daily Fleet Milage | C16: =C11*C15 -> 648
B18: Active Fleet Size | C18: ='Project Details'!C4*0.8 -> 120
B20: Daily Unit Milage | C20: =C16/C18 -> 5.4
B21: Unit Milage Range | C21: ='Project Details'!C9 -> 18
B22: Daily Unit Capacity Usage | C22: =C20/C21 -> 0.3

Sheet Electicity
A1: Parameter | B1: Value
A2: Average Montly Miles | B2: =Usability!I4 -> 10385.753
A3: NIU KQi 100P Range | B3: ='Project Details'!C9 -> 18
A4: Average Montly Charges | B4: =B2/B3 -> 576.9863
A5: Battery Capacity (kWh) | B5: 0.243
A6: Average Monthly Energy (kWh) | B6: =B4*B5 -> 140.20767
A7: Energy Cost /kWh | B7: 0.4
A8: Charger Hub Parastic Loss | B8: 0.25
A10: Average Monthly Energy Bill | B10: =B6*B7*(1+B8) -> 70.103836

Sheet Shipping
A1: Project Startup Order
A2: Item | B2: Supplier | C2: Quantity | D2: Aprox Unit/Weight(lb) | E2: Total Item Weight (lb) | F2: Rate/lb | G2: Base Fee | H2: Total
A3: Fleet | B3: NIU | C3: ='Project Details'!C4 -> 150 | D3: 38 | E3: =C3*D3 -> 5700 | F3: 0.42 | G3: 0 | H3: =F3*E3+G3 -> 2394
A4: Tires | B4: NIU | C4: ='Project Details'!G11 -> 6 | D4: 8 | E4: =C4*D4 -> 48 | F4: 0.42 | G4: 0 | H4: =F4*E4+G4 -> 20.16
A5: Brakes | B5: NIU | C5: ='Project Details'!G12 -> 9 | D5: 1 | E5: =C5*D5 -> 9 | F5: 0.42 | G5: 0 | H5: =F5*E5+G5 -> 3.78
A6: Batteries | B6: NIU | C6: ='Project Details'!G13 -> 6 | D6: 5 | E6: =C6*D6 -> 30 | F6: 0.42 | G6: 0 | H6: =F6*E6+G6 -> 12.6
A7: Frame | B7: NIU | C7: ='Project Details'!G14 -> 2 | D7: 20 | E7: =C7*D7 -> 40 | F7: 0.42 | G7: 0 | H7: =F7*E7+G7 -> 16.8
A8: Controller | B8: NIU | C8: ='Project Details'!G15 -> 5 | D8: 3.5 | E8: =C8*D8 -> 17.5 | F8: 0.42 | G8: 0 | H8: =F8*E8+G8 -> 7.35
A9: Lights | B9: NIU | C9: ='Project Details'!G16 -> 9 | D9: 0.5 | E9: =C9*D9 -> 4.5 | F9: 0.42 | G9: 100 | H9: =F9*E9+G9 -> 101.89
A10: MLCS Adapters | B10: Kuhmute | C10: ='Project Details'!C4 -> 150 | D10: 1 | E10: =C10*D10 -> 150 | F10: 0.42 | G10: 100 | H10: =F10*E10+G10 -> 163
A11: Kuhmute Smart Hub | B11: Kuhmute | C11: ='Project Details'!C21 -> 6 | D11: 450 | E11: =C11*D11 -> 2700 | F11: 0.42 | G11: 250 | H11: =F11*E11+G11 -> 1384
A12: IoT Modules | B12: Joyride | C12: ='Project Details'!C4 -> 150 | D12: 0.5 | E12: =C12*D12 -> 75 | F12: 0.42 | G12: 100 | H12: =F12*E12+G12 -> 131.5
A13: Total | C13: =SUM(C3:C12) -> 493 | E13: =SUM(E1:E3) -> 5700 | H13: =SUM(H3:H12) -> 4235.08
A16: Monthly Parts Order
A17: Item | B17: Supplier | C17: Quantity | D17: Aprox Unit/Weight(lb) | E17: Total Item Weight (lb) | F17: Rate/lb | G17: Base Fee | H17: Total
A18: Tires | B18: NIU | C18: =(Maintenance!G4+Maintenance!G16)/12 -> 24.954452 | D18: 8 | E18: =C18*D18 -> 199.63562 | F18: 0.42 | G18: 0 | H18: =F18*E18+G18 -> 83.846959
A19: Brakes | B19: NIU | C19: =(Maintenance!G5+Maintenance!G17)/12 -> 14.164726 | D19: 1 | E19: =C19*D19 -> 14.164726 | F19: 0.42 | G19: 0 | H19: =F19*E19+G19 -> 5.9491849
A20: Batteries | B20: NIU | C20: =(Maintenance!G6+Maintenance!G18)/12 -> 9.8640411 | D20: 5 | E20: =C20*D20 -> 49.320205 | F20: 0.42 | G20: 0 | H20: =F20*E20+G20 -> 20.714486
A21: Frame | B21: NIU | C21: =(Maintenance!G7+Maintenance!G19)/12 -> 4.845797 | D21: 20 | E21: =C21*D21 -> 96.91594 | F21: 0.42 | G21: 0 | H21: =F21*E21+G21 -> 40.704695
A22: Controller | B22: NIU | C22: =(Maintenance!G8+Maintenance!G20)/12 -> 6.095797 | D22: 3.5 | E22: =C22*D22 -> 21.33529 | F22: 0.42 | G22: 0 | H22: =F22*E22+G22 -> 8.9608216
A23: Lights | B23: NIU | C23: =(Maintenance!G9+Maintenance!G21)/12 -> 54.674813 | D23: 0.5 | E23: =C23*D23 -> 27.337407 | F23: 0.42 | G23: 100 | H23: =F23*E23+G23 -> 111.48171
A24: Total | C24: =SUM(C18:C23) -> 114.59963 | E24: =SUM(E18:E23) -> 408.70918 | H24: =SUM(H18:H23) -> 271.65786

Sheet CR Finance Options
B1: Capital Costs | G1: 5 Year Finance (25% Down) | J1: 3 Year Finance (25% Down) | M1: 1 Year Finance (25% Down)
B2: Stock Scooter Fleet | C2: ='Project Details'!C3*'Project Details'!C4*(1-'Project Details'!F3) -> 40500 | G2: Month | H2: $ | J2: Month | K2: $ | M2: Month | N2: $
B3: Retrofitting Labor | C3: ='Project Details'!F7*'Project Details'!C4*SUM('Project Details'!C35:C36) -> 22500 | G3: 0 | H3: =--'CR Finance Options'!C10*0.25 -> 73158.47 | J3: 0 | K3: ='CR Finance Options'!C10*0.25 -> 73158.47 | M3: 0 | N3: =0.25*'CR Finance Options'!C10 -> 73158.47
B4: GeoFencing System | C4: ='Project Details'!C17+'Project Details'!C16*'Project Details'!C4 -> 16000 | G4: 1 | H4: ='CR Finance Options'!$D$18 -> 4345.8762 | J4: 1 | K4: ='CR Finance Options'!$D$17 -> 6676.8672 | M4: 1 | N4: ='CR Finance Options'!$D$16 -> 18788.737
B5: Smart Hub Stations | C5: ='Project Details'!C21*SUM('Project Details'!C23:C24)+'Project Details'!C22*'Project Details'!C4 -> 106500 | G5: 2 | H5: ='CR Finance Options'!$D$18 -> 4345.8762 | J5: 2 | K5: ='CR Finance Options'!$D$17 -> 6676.8672 | M5: 2 | N5: ='CR Finance Options'!$D$16 -> 18788.737
B6: Site Development | C6: =(1+'Project Details'!C32)*SUM('Project Details'!C27:C31) -> 92400 | G6: 3 | H6: ='CR Finance Options'!$D$18 -> 4345.8762 | J6: 3 | K6: ='CR Finance Options'!$D$17 -> 6676.8672 | M6: 3 | N6: ='CR Finance Options'!$D$16 -> 18788.737
B7: Permits | C7: =SUM('Project Details'!C39:C43) -> 8500 | G7: 4 | H7: ='CR Finance Options'!$D$18 -> 4345.8762 | J7: 4 | K7: ='CR Finance Options'!$D$17 -> 6676.8672 | M7: 4 | N7: ='CR Finance Options'!$D$16 -> 18788.737
B8: Spare Parts | C8: ='Project Details'!I17 -> 1998.8 | G8: 5 | H8: ='CR Finance Options'!$D$18 -> 4345.8762 | J8: 5 | K8: ='CR Finance Options'!$D$17 -> 6676.8672 | M8: 5 | N8: ='CR Finance Options'!$D$16 -> 18788.737
B9: Shipping | C9: =Shipping!H13 -> 4235.08 | G9: 6 | H9: ='CR Finance Options'!$D$18 -> 4345.8762 | J9: 6 | K9: ='CR Finance Options'!$D$17 -> 6676.8672 | M9: 6 | N9: ='CR Finance Options'!$D$16 -> 18788.737
B10: Total | C10: =SUM(C2:C9) -> 292633.88 | G10: 7 | H10: ='CR Finance Options'!$D$18 -> 4345.8762 | J10: 7 | K10: ='CR Finance Options'!$D$17 -> 6676.8672 | M10: 7 | N10: ='CR Finance Options'!$D$16 -> 18788.737
G11: 8 | H11: ='CR Finance Options'!$D$18 -> 4345.8762 | J11: 8 | K11: ='CR Finance Options'!$D$17 -> 6676.8672 | M11: 8 | N11: ='CR Finance Options'!$D$16 -> 18788.737
G12: 9 | H12: ='CR Finance Options'!$D$18 -> 4345.8762 | J12: 9 | K12: ='CR Finance Options'!$D$17 -> 6676.8672 | M12: 9 | N12: ='CR Finance Options'!$D$16 -> 18788.737
G13: 10 | H13: ='CR Finance Options'!$D$18 -> 4345.8762 | J13: 10 | K13: ='CR Finance Options'!$D$17 -> 6676.8672 | M13: 10 | N13: ='CR Finance Options'!$D$16 -> 18788.737
B14: Finance Options | G14: 11 | H14: ='CR Finance Options'!$D$18 -> 4345.8762 | J14: 11 | K14: ='CR Finance Options'!$D$17 -> 6676.8672 | M14: 11 | N14: ='CR Finance Options'!$D$16 -> 18788.737
B15: Years | C15: Nominal Interest Rates | D15: Monthly Annuity (25% Down) | E15: Option PV vs MARR | G15: 12 | H15: ='CR Finance Options'!$D$18 -> 4345.8762 | J15: 12 | K15: ='CR Finance Options'!$D$17 -> 6676.8672 | M15: 12 | N15: ='CR Finance Options'!$D$16 -> 18788.737
B16: 1 | C16: 0.05 | D16: =-PMT(C16/12,B16*12,'CR Finance Options'!$C$10*0.75) -> 18788.737 | E16: =N64 -> 289470.53 | G16: 13 | H16: ='CR Finance Options'!$D$18 -> 4345.8762 | J16: 13 | K16: ='CR Finance Options'!$D$17 -> 6676.8672 | M16: 13 | N16: 0
B17: 3 | C17: 0.06 | D17: =-PMT(C17/12,B17*12,'CR Finance Options'!$C$10*0.75) -> 6676.8672 | E17: =K64 -> 287107.54 | G17: 14 | H17: ='CR Finance Options'!$D$18 -> 4345.8762 | J17: 14 | K17: ='CR Finance Options'!$D$17 -> 6676.8672 | M17: 14 | N17: 0
B18: 5 | C18: 0.07 | D18: =-PMT(C18/12,B18*12,'CR Finance Options'!$C$10*0.75) -> 4345.8762 | E18: =H64 -> 288909.07 | G18: 15 | H18: ='CR Finance Options'!$D$18 -> 4345.8762 | J18: 15 | K18: ='CR Finance Options'!$D$17 -> 6676.8672 | M18: 15 | N18: 0
G19: 16 | H19: ='CR Finance Options'!$D$18 -> 4345.8762 | J19: 16 | K19: ='CR Finance Options'!$D$17 -> 6676.8672 | M19: 16 | N19: 0
G20: 17 | H20: ='CR Finance Options'!$D$18 -> 4345.8762 | J20: 17 | K20: ='CR Finance Options'!$D$17 -> 6676.8672 | M20: 17 | N20: 0
G21: 18 | H21: ='CR Finance Options'!$D$18 -> 4345.8762 | J21: 18 | K21: ='CR Finance Options'!$D$17 -> 6676.8672 | M21: 18 | N21: 0
D22: Year Option Selected | E22: =_xlfn.XLOOKUP(MIN(E16:E18),E16:E18,B16:B18) -> 3 | G22: 19 | H22: ='CR Finance Options'!$D$18 -> 4345.8762 | J22: 19 | K22: ='CR Finance Options'!$D$17 -> 6676.8672 | M22: 19 | N22: 0
G23: 20 | H23: ='CR Finance Options'!$D$18 -> 4345.8762 | J23: 20 | K23: ='CR Finance Options'!$D$17 -> 6676.8672 | M23: 20 | N23: 0
G24: 21 | H24: ='CR Finance Options'!$D$18 -> 4345.8762 | J24: 21 | K24: ='CR Finance Options'!$D$17 -> 6676.8672 | M24: 21 | N24: 0
G25: 22 | H25: ='CR Finance Options'!$D$18 -> 4345.8762 | J25: 22 | K25: ='CR Finance Options'!$D$17 -> 6676.8672 | M25: 22 | N25: 0
G26: 23 | H26: ='CR Finance Options'!$D$18 -> 4345.8762 | J26: 23 | K26: ='CR Finance Options'!$D$17 -> 6676.8672 | M26: 23 | N26: 0
G27: 24 | H27: ='CR Finance Options'!$D$18 -> 4345.8762 | J27: 24 | K27: ='CR Finance Options'!$D$17 -> 6676.8672 | M27: 24 | N27: 0
G28: 25 | H28: ='CR Finance Options'!$D$18 -> 4345.8762 | J28: 25 | K28: ='CR Finance Options'!$D$17 -> 6676.8672 | M28: 25 | N28: 0
G29: 26 | H29: ='CR Finance Options'!$D$18 -> 4345.8762 | J29: 26 | K29: ='CR Finance Options'!$D$17 -> 6676.8672 | M29: 26 | N29: 0
G30: 27 | H30: ='CR Finance Options'!$D$18 -> 4345.8762 | J30: 27 | K30: ='CR Finance Options'!$D$17 -> 6676.8672 | M30: 27 | N30: 0
G31: 28 | H31: ='CR Finance Options'!$D$18 -> 4345.8762 | J31: 28 | K31: ='CR Finance Options'!$D$17 -> 6676.8672 | M31: 28 | N31: 0
G32: 29 | H32: ='CR Finance Options'!$D$18 -> 4345.8762 | J32: 29 | K32: ='CR Finance Options'!$D$17 -> 6676.8672 | M32: 29 | N32: 0
G33: 30 | H33: ='CR Finance Options'!$D$18 -> 4345.8762 | J33: 30 | K33: ='CR Finance Options'!$D$17 -> 6676.8672 | M33: 30 | N33: 0
G34: 31 | H34: ='CR Finance Options'!$D$18 -> 4345.8762 | J34: 31 | K34: ='CR Finance Options'!$D$17 -> 6676.8672 | M34: 31 | N34: 0
... G39: 36 | H39: ='CR Finance Options'!$D$18 -> 4345.8762 | J39: 36 | K39: ='CR Finance Options'!$D$17 -> 6676.8672 | M39: 36 | N39: 0
G40: 37 | H40: ='CR Finance Options'!$D$18 -> 4345.8762 | J40: 37 | K40: 0 | M40: 37 | N40: 0
G41: 38 | H41: ='CR Finance Options'!$D$18 -> 4345.8762 | J41: 38 | K41: 0 | M41: 38 | N41: 0
G42: 39 | H42: ='CR Finance Options'!$D$18 -> 4345.8762 | J42: 39 | K42: 0 | M42: 39 | N42: 0
G43: 40 | H43: ='CR Finance Options'!$D$18 -> 4345.8762 | J43: 40 | K43: 0 | M43: 40 | N43: 0
G44: 41 | H44: ='CR Finance Options'!$D$18 -> 4345.8762 | J44: 41 | K44: 0 | M44: 41 | N44: 0
...

Sheet Revenue
B2: Student Annual Fee | H2: Inflated Revenue
B3: Adoption % | C3: Opt-in Users | D3: Fee | E3: Revenue | H3: Year | I3: Cash In
B4: =Usability!C10 -> 0.12 | C4: =Usability!C14 -> 864 | D4: ='PROJECT ANALYSIS'!B4 -> 180 | E4: =C4*D4 -> 155520 | H4: 1 | I4: =($E$8+$E$4)*('Project Details'!$F$5+1)^(H4-1) -> 217834.52
H5: =1+H4 -> 2 | I5: =($E$8+$E$4)*('Project Details'!$F$5+1)^H5 -> 233349.78
B6: Per Mile Fee | H6: =1+H5 -> 3 | I6: =($E$8+$E$4)*('Project Details'!$F$5+1)^H6 -> 241517.03
B7: Annual miles | D7: $/mile | E7: Revenue | H7: =1+H6 -> 4 | I7: =($E$8+$E$4)*('Project Details'!$F$5+1)^H7 -> 249970.12
B8: =Usability!I4*12 -> 124629.04 | D8: 0.5 | E8: =B8*D8 -> 62314.521 | H8: =1+H7 -> 5 | I8: =($E$8+$E$4)*('Project Details'!$F$5+1)^H8 -> 258719.08

Sheet Cashflow
A1: Inflation Factor | B1: Month | C1: Finance Payments | D1: Electrcity | E1: Joyride Scale Plan | F1: Permit | G1: Parts | H1: Labor Cost | I1: Per Mile Revenue | J1: Student Fee Revenue | K1: Net Cash Flow | L1: Discounted Outflow | M1: Discounted Inflow | N1: Discounted Project Value
A2: =(1+'Project Details'!$F$5)^(B2/12) -> 1 | B2: 0 | C2: =-'CR Finance Options'!K3 -> -73158.47 | D2: 0 | E2: =-Cashflow!A2*'Project Details'!$C$14 -> -2500 | F2: =IF(MOD(B2,12)=0,-A2*'Project Details'!$C$44,0) -> -2500 | G2: 0 | H2: 0 | I2: 0 | J2: =IF(MOD(B2,12)=0,Revenue!$E$4*A2,0) -> 155520 | K2: =SUM(C2:J2) -> 77361.53 | L2: =SUM(C2:H2)/((1+'Project Details'!$F$6)^(B2/12)) -> -78158.47 | M2: =SUM(I2:J2)/((1+'Project Details'!$F$6)^(B2/12)) -> 155520 | N2: =K2 -> 77361.53
A3: =(1+'Project Details'!$F$5)^(B3/12) -> 1.0028709 | B3: 1 | C3: =-'CR Finance Options'!K4 -> -6676.8672 | D3: =-A3*Electicity!$B$10 -> -70.305097 | E3: =-Cashflow!A3*'Project Details'!$C$14 -> -2507.1772 | F3: =IF(MOD(B3,12)=0,-A3*'Project Details'!$C$44,0) -> 0 | G3: =-(Shipping!$H$24+Maintenance!$G$24)*Cashflow!A3 -> -3121.099 | H3: =-Maintenance!$G$25*A3 -> -3662.9766 | I3: =Revenue!$E$8/12 -> 5192.8767 | J3: =IF(MOD(B3,12)=0,Revenue!$E$4*A3,0) -> 0 | K3: =SUM(C3:J3) -> -10845.548 | L3: =SUM(C3:H3)/((1+'Project Details'!$F$6)^(B3/12)) -> -15935.893 | M3: =SUM(I3:J3)/((1+'Project Details'!$F$6)^(B3/12)) -> 5159.6792 | N3: =$K$2+NPV((1+'Project Details'!$F$6)^(1/12)-1,$K$3:K3) -> 66585.316
A4: =(1+'Project Details'!$F$5)^(B4/12) -> 1.00575 | B4: 2 | C4: =-'CR Finance Options'!K5 -> -6676.8672 | D4: =-A4*Electicity!$B$10 -> -70.506935 | E4: =-Cashflow!A4*'Project Details'!$C$14 -> -2514.3751 | F4: =IF(MOD(B4,12)=0,-A4*'Project Details'!$C$44,0) -> 0 | G4: =-(Shipping!$H$24+Maintenance!$G$24)*Cashflow!A4 -> -3130.0594 | H4: =-Maintenance!$G$25*A4 -> -3673.4926 | I4: =Revenue!$E$8/12 -> 5192.8767 | J4: =IF(MOD(B4,12)=0,Revenue!$E$4*A4,0) -> 0 | K4: =SUM(C4:J4) -> -10872.425 | L4: =SUM(C4:H4)/((1+'Project Details'!$F$6)^(B4/12)) -> -15860.55 | M4: =SUM(I4:J4)/((1+'Project Details'!$F$6)^(B4/12)) -> 5126.6939 | N4: =$K$2+NPV((1+'Project Details'!$F$6)^(1/12)-1,$K$3:K4) -> 55851.46 | Q4: CSUEB NIU KQi 100P Scooter Fleet
A5: =(1+'Project Details'!$F$5)^(B5/12) -> 1.0086374 | B5: 3 | C5: =-'CR Finance Options'!K6 -> -6676.8672 | D5: =-A5*Electicity!$B$10 -> -70.709354 | E5: =-Cashflow!A5*'Project Details'!$C$14 -> -2521.5936 | F5: =IF(MOD(B5,12)=0,-A5*'Project Details'!$C$44,0) -> 0 | G5: =-(Shipping!$H$24+Maintenance!$G$24)*Cashflow!A5 -> -3139.0455 | H5: =-Maintenance!$G$25*A5 -> -3684.0389 | I5: =Revenue!$E$8/12 -> 5192.8767 | J5: =IF(MOD(B5,12)=0,Revenue!$E$4*A5,0) -> 0 | K5: =SUM(C5:J5) -> -10899.378 | L5: =SUM(C5:H5)/((1+'Project Details'!$F$6)^(B5/12)) -> -15785.595 | M5: =SUM(I5:J5)/((1+'Project Details'!$F$6)^(B5/12)) -> 5093.9194 | N5: =$K$2+NPV((1+'Project Details'!$F$6)^(1/12)-1,$K$3:K5) -> 45159.784 | Q5: NPV | R5: =K2+NPV(('Project Details'!F6+1)^(1/12)-1,Cashflow!K3:K62) -> 168525.43
A6: =(1+'Project Details'!$F$5)^(B6/12) -> 1.0115331 | B6: 4 | C6: =-'CR Finance Options'!K7 -> -6676.8672 | D6: =-A6*Electicity!$B$10 -> -70.912353 | E6: =-Cashflow!A6*'Project Details'!$C$14 -> -2528.8329 | F6: =IF(MOD(B6,12)=0,-A6*'Project Details'!$C$44,0) -> 0 | G6: =-(Shipping!$H$24+Maintenance!$G$24)*Cashflow!A6 -> -3148.0574 | H6: =-Maintenance!$G$25*A6 -> -3694.6154 | I6: =Revenue!$E$8/12 -> 5192.8767 | J6: =IF(MOD(B6,12)=0,Revenue!$E$4*A6,0) -> 0 | K6: =SUM(C6:J6) -> -10926.408 | L6: =SUM(C6:H6)/((1+'Project Details'!$F$6)^(B6/12)) -> -15711.025 | M6: =SUM(I6:J6)/((1+'Project Details'!$F$6)^(B6/12)) -> 5061.3545 | N6: =$K$2+NPV((1+'Project Details'!$F$6)^(1/12)-1,$K$3:K6) -> 34510.114 | Q6: AEC | R6: =-PMT('Project Details'!F6,'Project Details'!F4,Cashflow!R5) -> 42208.281
A7: =(1+'Project Details'!$F$5)^(B7/12) -> 1.0144372 | B7: 5 | C7: =-'CR Finance Options'!K8 -> -6676.8672 | D7: =-A7*Electicity!$B$10 -> -71.115935 | E7: =-Cashflow!A7*'Project Details'!$C$14 -> -2536.0929 | F7: =IF(MOD(B7,12)=0,-A7*'Project Details'!$C$44,0) -> 0 | G7: =-(Shipping!$H$24+Maintenance!$G$24)*Cashflow!A7 -> -3157.0951 | H7: =-Maintenance!$G$25*A7 -> -3705.2222 | I7: =Revenue!$E$8/12 -> 5192.8767 | J7: =IF(MOD(B7,12)=0,Revenue!$E$4*A7,0) -> 0 | K7: =SUM(C7:J7) -> -10953.517 | L7: =SUM(C7:H7)/((1+'Project Details'!$F$6)^(B7/12)) -> -15636.839 | M7: =SUM(I7:J7)/((1+'Project Details'!$F$6)^(B7/12)) -> 5028.9978 | N7: =$K$2+NPV((1+'Project Details'!$F$6)^(1/12)-1,$K$3:K7) -> 23902.273
A8: =(1+'Project Details'!$F$5)^(B8/12) -> 1.0173495 | B8: 6 | C8: =-'CR Finance Options'!K9 -> -6676.8672 | D8: =-A8*Electicity!$B$10 -> -71.320102 | E8: =-Cashflow!A8*'Project Details'!$C$14 -> -2543.3737 | F8: =IF(MOD(B8,12)=0,-A8*'Project Details'!$C$44,0) -> 0 | G8: =-(Shipping!$H$24+Maintenance!$G$24)*Cashflow!A8 -> -3166.1588 | H8: =-Maintenance!$G$25*A8 -> -3715.8595 | I8: =Revenue!$E$8/12 -> 5192.8767 | J8: =IF(MOD(B8,12)=0,Revenue!$E$4*A8,0) -> 0 | K8: =SUM(C8:J8) -> -10980.703 | L8: =SUM(C8:H8)/((1+'Project Details'!$F$6)^(B8/12)) -> -15563.034 | M8: =SUM(I8:J8)/((1+'Project Details'!$F$6)^(B8/12)) -> 4996.8479 | N8: =$K$2+NPV((1+'Project Details'!$F$6)^(1/12)-1,$K$3:K8) -> 13336.086
A9: =(1+'Project Details'!$F$5)^(B9/12) -> 1.0202702 | B9: 7 | C9: =-'CR Finance Options'!K10 -> -6676.8672 | D9: =-A9*Electicity!$B$10 -> -71.524855 | E9: =-Cashflow!A9*'Project Details'!$C$14 -> -2550.6755 | F9: =IF(MOD(B9,12)=0,-A9*'Project Details'!$C$44,0) -> 0 | G9: =-(Shipping!$H$24+Maintenance!$G$24)*Cashflow!A9 -> -3175.2485 | H9: =-Maintenance!$G$25*A9 -> -3726.5274 | I9: =Revenue!$E$8/12 -> 5192.8767 | J9: =IF(MOD(B9,12)=0,Revenue!$E$4*A9,0) -> 0 | K9: =SUM(C9:J9) -> -11007.967 | L9: =SUM(C9:H9)/((1+'Project Details'!$F$6)^(B9/12)) -> -15489.608 | M9: =SUM(I9:J9)/((1+'Project Details'!$F$6)^(B9/12)) -> 4964.9036 | N9: =$K$2+NPV((1+'Project Details'!$F$6)^(1/12)-1,$K$3:K9) -> 2811.3818
A10: =(1+'Project Details'!$F$5)^(B10/12) -> 1.0231993 | B10: 8 | C10: =-'CR Finance Options'!K11 -> -6676.8672 | D10: =-A10*Electicity!$B$10 -> -71.730195 | E10: =-Cashflow!A10*'Project Details'!$C$14 -> -2557.9982 | F10: =IF(MOD(B10,12)=0,-A10*'Project Details'!$C$44,0) -> 0 | G10: =-(Shipping!$H$24+Maintenance!$G$24)*Cashflow!A10 -> -3184.3643 | H10: =-Maintenance!$G$25*A10 -> -3737.2259 | I10: =Revenue!$E$8/12 -> 5192.8767 | J10: =IF(MOD(B10,12)=0,Revenue!$E$4*A10,0) -> 0 | K10: =SUM(C10:J10) -> -11035.309 | L10: =SUM(C10:H10)/((1+'Project Details'!$F$6)^(B10/12)) -> -15416.56 | M10: =SUM(I10:J10)/((1+'Project Details'!$F$6)^(B10/12)) -> 4933.1635 | N10: =$K$2+NPV((1+'Project Details'!$F$6)^(1/12)-1,$K$3:K10) -> -7672.0145
A11: =(1+'Project Details'!$F$5)^(B11/12) -> 1.0261368 | B11: 9 | C11: =-'CR Finance Options'!K12 -> -6676.8672 | D11: =-A11*Electicity!$B$10 -> -71.936125 | E11: =-Cashflow!A11*'Project Details'!$C$14 -> -2565.342 | F11: =IF(MOD(B11,12)=0,-A11*'Project Details'!$C$44,0) -> 0 | G11: =-(Shipping!$H$24+Maintenance!$G$24)*Cashflow!A11 -> -3193.5063 | H11: =-Maintenance!$G$25*A11 -> -3747.9551 | I11: =Revenue!$E$8/12 -> 5192.8767 | J11: =IF(MOD(B11,12)=0,Revenue!$E$4*A11,0) -> 0 | K11: =SUM(C11:J11) -> -11062.73 | L11: =SUM(C11:H11)/((1+'Project Details'!$F$6)^(B11/12)) -> -15343.886 | M11: =SUM(I11:J11)/((1+'Project Details'!$F$6)^(B11/12)) -> 4901.6263 | N11: =$K$2+NPV((1+'Project Details'!$F$6)^(1/12)-1,$K$3:K11) -> -18114.274
A12: =(1+'Project Details'!$F$5)^(B12/12) -> 1.0290827 | B12: 10 | C12: =-'CR Finance Options'!K13 -> -6676.8672 | D12: =-A12*Electicity!$B$10 -> -72.142647 | E12: =-Cashflow!A12*'Project Details'!$C$14 -> -2572.7068 | F12: =IF(MOD(B12,12)=0,-A12*'Project Details'!$C$44,0) -> 0 | G12: =-(Shipping!$H$24+Maintenance!$G$24)*Cashflow!A12 -> -3202.6746 | H12: =-Maintenance!$G$25*A12 -> -3758.7151 | I12: =Revenue!$E$8/12 -> 5192.8767 | J12: =IF(MOD(B12,12)=0,Revenue!$E$4*A12,0) -> 0 | K12: =SUM(C12:J12) -> -11090.23 | L12: =SUM(C12:H12)/((1+'Project Details'!$F$6)^(B12/12)) -> -15271.586 | M12: =SUM(I12:J12)/((1+'Project Details'!$F$6)^(B12/12)) -> 4870.2907 | N12: =$K$2+NPV((1+'Project Details'!$F$6)^(1/12)-1,$K$3:K12) -> -28515.569
A13: =(1+'Project Details'!$F$5)^(B13/12) -> 1.0320371 | B13: 11 | C13: =-'CR Finance Options'!K14 -> -6676.8672 | D13: =-A13*Electicity!$B$10 -> -72.349761 | E13: =-Cashflow!A13*'Project Details'!$C$14 -> -2580.0928 | F13: =IF(MOD(B13,12)=0,-A13*'Project Details'!$C$44,0) -> 0 | G13: =-(Shipping!$H$24+Maintenance!$G$24)*Cashflow!A13 -> -3211.8691 | H13: =-Maintenance!$G$25*A13 -> -3769.506 | I13: =Revenue!$E$8/12 -> 5192.8767 | J13: =IF(MOD(B13,12)=0,Revenue!$E$4*A13,0) -> 0 | K13: =SUM(C13:J13) -> -11117.808 | L13: =SUM(C13:H13)/((1+'Project Details'!$F$6)^(B13/12)) -> -15199.656 | M13: =SUM(I13:J13)/((1+'Project Details'!$F$6)^(B13/12)) -> 4839.1554 | N13: =$K$2+NPV((1+'Project Details'!$F$6)^(1/12)-1,$K$3:K13) -> -38876.07
A14: =(1+'Project Details'!$F$5)^(B14/12) -> 1.035 | B14: 12 | C14: =-'CR Finance Options'!K15 -> -6676.8672 | D14: =-A14*Electicity!$B$10 -> -72.55747 | E14: =-Cashflow!A14*'Project Details'!$C$14 -> -2587.5 | F14: =IF(MOD(B14,12)=0,-A14*'Project Details'!$C$44,0) -> -2587.5 | G14: =-(Shipping!$H$24+Maintenance!$G$24)*Cashflow!A14 -> -3221.0901 | H14: =-Maintenance!$G$25*A14 -> -3780.3278 | I14: =Revenue!$E$8/12 -> 5192.8767 | J14: =IF(MOD(B14,12)=0,Revenue!$E$4*A14,0) -> 160963.2 | K14: =SUM(C14:J14) -> 147230.23 | L14: =SUM(C14:H14)/((1+'Project Details'!$F$6)^(B14/12)) -> -17523.928 | M14: =SUM(I14:J14)/((1+'Project Details'!$F$6)^(B14/12)) -> 153848.22 | N14: =$K$2+NPV((1+'Project Details'!$F$6)^(1/12)-1,$K$3:K14) -> 97448.221
A15: =(1+'Project Details'!$F$5)^(B15/12) -> 1.0379714 | B15: 13 | C15: =-'CR Finance Options'!K16 -> -6676.8672 | D15: =-A15*Electicity!$B$10 -> -72.765775 | E15: =-Cashflow!A15*'Project Details'!$C$14 -> -2594.9285 | F15: =IF(MOD(B15,12)=0,-A15*'Project Details'!$C$44,0) -> 0 | G15: =-(Shipping!$H$24+Maintenance!$G$24)*Cashflow!A15 -> -3230.3375 | H15: =-Maintenance!$G$25*A15 -> -3791.1808 | I15: =Revenue!$E$8/12 -> 5192.8767 | J15: =IF(MOD(B15,12)=0,Revenue!$E$4*A15,0) -> 0 | K15: =SUM(C15:J15) -> -11173.203 | L15: =SUM(C15:H15)/((1+'Project Details'!$F$6)^(B15/12)) -> -15056.901 | M15: =SUM(I15:J15)/((1+'Project Details'!$F$6)^(B15/12)) -> 4777.4807 | N15: =$K$2+NPV((1+'Project Details'!$F$6)^(1/12)-1,$K$3:K15) -> 87168.801
A16: =(1+'Project Details'!$F$5)^(B16/12) -> 1.0409513 | B16: 14 | C16: =-'CR Finance Options'!K17 -> -6676.8672 | D16: =-A16*Electicity!$B$10 -> -72.974678 | E16: =-Cashflow!A16*'Project Details'!$C$14 -> -2602.3782 | F16: =IF(MOD(B16,12)=0,-A16*'Project Details'!$C$44,0) -> 0 | G16: =-(Shipping!$H$24+Maintenance!$G$24)*Cashflow!A16 -> -3239.6115 | H16: =-Maintenance!$G$25*A16 -> -3802.0649 | I16: =Revenue!$E$8/12 -> 5192.8767 | J16: =IF(MOD(B16,12)=0,Revenue!$E$4*A16,0) -> 0 | K16: =SUM(C16:J16) -> -11201.02 | L16: =SUM(C16:H16)/((1+'Project Details'!$F$6)^(B16/12)) -> -14986.072 | M16: =SUM(I16:J16)/((1+'Project Details'!$F$6)^(B16/12)) -> 4746.9388 | N16: =$K$2+NPV((1+'Project Details'!$F$6)^(1/12)-1,$K$3:K16) -> 76929.668
A17: =(1+'Project Details'!$F$5)^(B17/12) -> 1.0439398 | B17: 15 | C17: =-'CR Finance Options'!K18 -> -6676.8672 | D17: =-A17*Electicity!$B$10 -> -73.184181 | E17: =-Cashflow!A17*'Project Details'!$C$14 -> -2609.8494 | F17: =IF(MOD(B17,12)=0,-A17*'Project Details'!$C$44,0) -> 0 | G17: =-(Shipping!$H$24+Maintenance!$G$24)*Cashflow!A17 -> -3248.9121 | H17: =-Maintenance!$G$25*A17 -> -3812.9802 | I17: =Revenue!$E$8/12 -> 5192.8767 | J17: =IF(MOD(B17,12)=0,Revenue!$E$4*A17,0) -> 0 | K17: =SUM(C17:J17) -> -11228.916 | L17: =SUM(C17:H17)/((1+'Project Details'!$F$6)^(B17/12)) -> -14915.605 | M17: =SUM(I17:J17)/((1+'Project Details'!$F$6)^(B17/12)) -> 4716.5921 | N17: =$K$2+NPV((1+'Project Details'!$F$6)^(1/12)-1,$K$3:K17) -> 66730.655
A18: =(1+'Project Details'!$F$5)^(B18/12) -> 1.0469368 | B18: 16 | C18: =-'CR Finance Options'!K19 -> -6676.8672 | D18: =-A18*Electicity!$B$10 -> -73.394285 | E18: =-Cashflow!A18*'Project Details'!$C$14 -> -2617.342 | F18: =IF(MOD(B18,12)=0,-A18*'Project Details'!$C$44,0) -> 0 | G18: =-(Shipping!$H$24+Maintenance!$G$24)*Cashflow!A18 -> -3258.2394 | H18: =-Maintenance!$G$25*A18 -> -3823.9269 | I18: =Revenue!$E$8/12 -> 5192.8767 | J18: =IF(MOD(B18,12)=0,Revenue!$E$4*A18,0) -> 0 | K18: =SUM(C18:J18) -> -11256.893 | L18: =SUM(C18:H18)/((1+'Project Details'!$F$6)^(B18/12)) -> -14845.5 | M18: =SUM(I18:J18)/((1+'Project Details'!$F$6)^(B18/12)) -> 4686.4394 | N18: =$K$2+NPV((1+'Project Details'!$F$6)^(1/12)-1,$K$3:K18) -> 56571.595
... A61: =(1+'Project Details'!$F$5)^(B61/12) -> 1.1842863 | B61: 59 | C61: =-'CR Finance Options'!K62 -> 0 | D61: =-A61*Electicity!$B$10 -> -83.023015 | E61: =-Cashflow!A61*'Project Details'!$C$14 -> -2960.7158 | F61: =IF(MOD(B61,12)=0,-A61*'Project Details'!$C$44,0) -> 0 | G61: =-(Shipping!$H$24+Maintenance!$G$24)*Cashflow!A61 -> -3685.6937 | H61: =-Maintenance!$G$25*A61 -> -4325.5948 | I61: =Revenue!$E$8/12 -> 5192.8767 | J61: =IF(MOD(B61,12)=0,Revenue!$E$4*A61,0) -> 0 | K61: =SUM(C61:J61) -> -5862.1506 | L61: =SUM(C61:H61)/((1+'Project Details'!$F$6)^(B61/12)) -> -7572.2746 | M61: =SUM(I61:J61)/((1+'Project Details'!$F$6)^(B61/12)) -> 3556.9237 | N61: =$K$2+NPV((1+'Project Details'!$F$6)^(1/12)-1,$K$3:K61) -> 172536.71
A62: =(1+'Project Details'!$F$5)^(B62/12) -> 1.1876863 | B62: 60 | C62: =-'CR Finance Options'!K63 -> 0 | D62: =-A62*Electicity!$B$10 -> -83.261366 | E62: =-Cashflow!A62*'Project Details'!$C$14 -> -2969.2158 | F62: 0 | G62: =-(Shipping!$H$24+Maintenance!$G$24)*Cashflow!A62 -> -3696.2749 | H62: =-Maintenance!$G$25*A62 -> -4338.0131 | I62: =Revenue!$E$8/12 -> 5192.8767 | J62: 0 | K62: =SUM(C62:J62) -> -5893.8885 | L62: =SUM(C62:H62)/((1+'Project Details'!$F$6)^(B62/12)) -> -7545.4661 | M62: =SUM(I62:J62)/((1+'Project Details'!$F$6)^(B62/12)) -> 3534.1846 | N62: =$K$2+NPV((1+'Project Details'!$F$6)^(1/12)-1,$K$3:K62) -> 168525.43

Sheet Annual Cashflow
A1: Year | B1: Annual Revenue | C1: Annual Costs | D1: Cumulative NPV
A2: 1 | B2: =SUM(Cashflow!M2:M13) -> 210496.63 | C2: =ABS(SUM(Cashflow!L2:L13)) -> 249372.7 | D2: =B2-C2 -> -38876.07
A3: =1+A2 -> 2 | B3: =SUM(Cashflow!M14:M25) -> 204752.51 | C3: =ABS(SUM(Cashflow!L14:L25)) -> 179313.43 | D3: =B3-C3+D2 -> -13436.995
A4: =1+A3 -> 3 | B4: =SUM(Cashflow!M26:M37) -> 194415.66 | C4: =ABS(SUM(Cashflow!L26:L37)) -> 169520.58 | D4: =B4-C4+D3 -> 11458.082
A5: =1+A4 -> 4 | B5: =SUM(Cashflow!M38:M49) -> 184643.25 | C5: =ABS(SUM(Cashflow!L38:L49)) -> 104193.67 | D5: =B5-C5+D4 -> 91907.658
A6: =1+A5 -> 5 | B6: =SUM(Cashflow!M50:M62) -> 178936.04 | C6: =ABS(SUM(Cashflow!L50:L62)) -> 102318.27 | D6: =B6-C6+D5 -> 168525.43

Sheet PROJECT ANALYSIS
B3: 0.12 | C3: NPV | D3: Annual Student Fee
B4: 180 | C4: =Cashflow!R5 -> 168525.43 | D4: 180 | E4: =D4+10 -> 190 | F4: =E4+10 -> 200 | G4: =F4+10 -> 210 | H4: =G4+10 -> 220 | I4: =H4+10 -> 230 | J4: =I4+10 -> 240 | K4: =J4+10 -> 250
B5: Adoption % | C5: 0.1 | D5: 52913.318 | E5: 86035.735 | F5: 119158.15 | G5: 152280.57 | H5: 185402.99 | I5: 218525.41 | J5: 251647.82 | K5: 284770.24
C6: =C5+0.01 -> 0.11 | D6: 110719.37 | E6: 147154.03 | F6: 183588.69 | G6: 220023.35 | H6: 256458.01 | I6: 292892.67 | J6: 329327.33 | K6: 365761.99
C7: =C6+0.01 -> 0.12 | D7: 168525.43 | E7: 208272.33 | F7: 248019.23 | G7: 287766.13 | H7: 327513.03 | I7: 367259.93 | J7: 407006.83 | K7: 446753.74
C8: =C7+0.01 -> 0.13 | D8: 226331.48 | E8: 269390.63 | F8: 312449.77 | G8: 355508.91 | H8: 398568.05 | I8: 441627.2 | J8: 484686.34 | K8: 527745.48
C9: =C8+0.01 -> 0.14 | D9: 284137.54 | E9: 330508.92 | F9: 376880.31 | G9: 423251.69 | H9: 469623.08 | I9: 515994.46 | J9: 562365.85 | K9: 608737.23
C10: =C9+0.01 -> 0.15 | D10: 341943.59 | E10: 391627.22 | F10: 441310.85 | G10: 490994.47 | H10: 540678.1 | I10: 590361.73 | J10: 640045.35 | K10: 689728.98
C11: =C10+0.01 -> 0.16 | D11: 399749.65 | E11: 452745.52 | F11: 505741.38 | G11: 558737.25 | H11: 611733.12 | I11: 664728.99 | J11: 717724.86 | K11: 770720.73
C12: =C11+0.01 -> 0.17 | D12: 457555.7 | E12: 513863.81 | F12: 570171.92 | G12: 626480.03 | H12: 682788.14 | I12: 739096.25 | J12: 795404.36 | K12: 851712.47
C13: =C12+0.01 -> 0.18 | D13: 515361.76 | E13: 574982.11 | F13: 634602.46 | G13: 694222.81 | H13: 753843.17 | I13: 813463.52 | J13: 873083.87 | K13: 932704.22
C14: =C13+0.01 -> 0.19 | D14: 573167.81 | E14: 636100.41 | F14: 699033 | G14: 761965.59 | H14: 824898.19 | I14: 887830.78 | J14: 950763.37 | K14: 1013696
C15: =C14+0.01 -> 0.2 | D15: 630973.87 | E15: 697218.7 | F15: 763463.54 | G15: 829708.37 | H15: 895953.21 | I15: 962198.04 | J15: 1028442.9 | K15: 1094687.7
A17: %
A18: Fee
